{"id":332602,"title":"108 | Go 编程模式：错误处理","content":"<p>你好，我是陈皓，网名左耳朵耗子。</p><p>错误处理一直是编程必须要面对的问题。错误处理如果做得好的话，代码的稳定性会很好。不同的语言有不同的错误处理的方式。Go语言也一样，这节课，我们来讨论一下Go语言的错误出处，尤其是那令人抓狂的 <code>if err != nil</code> 。</p><p>在正式讨论“Go代码里满屏的 <code>if err != nil</code> 怎么办”这件事儿之前，我想先说一说编程中的错误处理。</p><h2>C语言的错误检查</h2><p>首先，我们知道，处理错误最直接的方式是通过错误码，这也是传统的方式，在过程式语言中通常都是用这样的方式处理错误的。比如 C 语言，基本上来说，其通过函数的返回值标识是否有错，然后通过全局的 <code>errno</code> 变量加一个 <code>errstr</code> 的数组来告诉你为什么出错。</p><p>为什么是这样的设计呢？道理很简单，除了可以共用一些错误，更重要的是这其实是一种妥协，比如：<code>read()</code>、  <code>write()</code>、  <code>open()</code> 这些函数的返回值其实是返回有业务逻辑的值，也就是说，这些函数的返回值有两种语义：</p><ol>\n<li>一种是成功的值，比如 <code>open()</code> 返回的文件句柄指针 <code>FILE*</code>  ；</li>\n<li>另一种是错误 <code>NULL</code>。这会导致调用者并不知道是什么原因出错了，需要去检查 <code>errno</code> 以获得出错的原因，从而正确地处理错误。</li>\n</ol><p>一般而言，这样的错误处理方式在大多数情况下是没什么问题的，不过也有例外的情况，我们来看一下下面这个 C 语言的函数：</p><!-- [[[read_end]]] --><pre><code>int atoi(const char *str)\n</code></pre><p>这个函数是把一个字符串转成整型。但是问题来了，如果一个要转的字符串是非法的（不是数字的格式），如 “ABC” 或者整型溢出了，那么这个函数应该返回什么呢？出错返回，返回什么数都不合理，因为这会和正常的结果混淆在一起。比如，如果返回 <code>0</code>，就会和正常的对 “0” 字符的返回值完全混淆在一起，这样就无法判断出错的情况了。你可能会说，是不是要检查一下 <code>errno</code>呢？按道理说应该是要去检查的，但是，我们在 C99 的规格说明书中可以看到这样的描述：</p><blockquote>\n<p><em>7.20.1The functions atof, atoi, atol, and atoll need not affect the value of the integer expression errno on an error. If the value of the result cannot be represented, the behavior is undeﬁned.</em></p>\n</blockquote><p>像<code>atoi()</code>、  <code>atof()</code>、  <code>atol()</code> 或 <code>atoll()</code> 这样的函数，是不会设置 <code>errno</code>的，而且，如果结果无法计算的话，行为是undefined。所以，后来，libc 又给出了一个新的函数<code>strtol()</code>，这个函数在出错的时候会设置全局变量 <code>errno</code> ：</p><pre><code>long val = strtol(in_str, &amp;endptr, 10);  //10的意思是10进制\n\n//如果无法转换\nif (endptr == str) {\n    fprintf(stderr, &quot;No digits were found\\n&quot;);\n    exit(EXIT_FAILURE);\n}\n\n//如果整型溢出了\nif ((errno == ERANGE &amp;&amp; (val == LONG_MAX || val == LONG_MIN)) {\n    fprintf(stderr, &quot;ERROR: number out of range for LONG\\n&quot;);\n    exit(EXIT_FAILURE);\n }\n\n//如果是其它错误\nif (errno != 0 &amp;&amp; val == 0) {\n    perror(&quot;strtol&quot;);\n    exit(EXIT_FAILURE);\n}\n</code></pre><p>虽然，<code>strtol()</code> 函数解决了 <code>atoi()</code> 函数的问题，但是我们还是能感觉到不是很舒服，也不是很自然。</p><p>因为这种用返回值 + errno 的错误检查方式会有一些问题：</p><ul>\n<li>程序员一不小心就会忘记检查返回值，从而造成代码的 Bug；</li>\n<li>函数接口非常不纯洁，正常值和错误值混淆在一起，导致语义有问题。</li>\n</ul><p>所以，后来有一些类库就开始区分这样的事情。比如，Windows 的系统调用开始使用 <code>HRESULT</code> 的返回来统一错误的返回值，这样可以明确函数调用时的返回值是成功还是错误。但这样一来，函数的 input 和 output 只能通过函数的参数来完成，于是就出现了所谓的“入参”和“出参”这样的区别。</p><p>然而，这又使得函数接入中参数的语义变得很复杂，一些参数是入参，一些参数是出参，函数接口变得复杂了一些。而且，依然没有解决函数的成功或失败可以被人为忽略的问题。</p><h2>Java的错误处理</h2><p>Java语言使用 <code>try-catch-finally</code> 通过使用异常的方式来处理错误，其实，这比起C语言的错误处理进了一大步，使用抛异常和抓异常的方式可以让我们的代码有这样一些好处。</p><ul>\n<li>函数接口在 input（参数）和 output（返回值）以及错误处理的语义是比较清楚的。</li>\n<li>正常逻辑的代码可以跟错误处理和资源清理的代码分开，提高了代码的可读性。</li>\n<li>异常不能被忽略（如果要忽略也需要 catch 住，这是显式忽略）。</li>\n<li>在面向对象的语言中（如 Java），异常是个对象，所以，可以实现多态式的 catch。</li>\n<li>与状态返回码相比，异常捕捉有一个显著的好处，那就是函数可以嵌套调用，或是链式调用，比如：</li>\n</ul><pre><code>int x = add(a, div(b,c));\nPizza p = PizzaBuilder().SetSize(sz).SetPrice(p)...;\n</code></pre><h2>Go语言的错误处理</h2><p>Go 语言的函数支持多返回值，所以，可以在返回接口把业务语义（业务返回值）和控制语义（出错返回值）区分开。Go 语言的很多函数都会返回 result、err 两个值，于是就有这样几点：</p><ul>\n<li>参数上基本上就是入参，而返回接口把结果和错误分离，这样使得函数的接口语义清晰；</li>\n<li>而且，Go 语言中的错误参数如果要忽略，需要显式地忽略，用 _ 这样的变量来忽略；</li>\n<li>另外，因为返回的 <code>error</code> 是个接口（其中只有一个方法 <code>Error()</code>，返回一个 <code>string</code> ），所以你可以扩展自定义的错误处理。</li>\n</ul><p>另外，如果一个函数返回了多个不同类型的 <code>error</code>，你也可以使用下面这样的方式：</p><pre><code>if err != nil {\n  switch err.(type) {\n    case *json.SyntaxError:\n      ...\n    case *ZeroDivisionError:\n      ...\n    case *NullPointerError:\n      ...\n    default:\n      ...\n  }\n}\n</code></pre><p>我们可以看到，<strong>Go语言的错误处理的方式，本质上是返回值检查，但是它也兼顾了异常的一些好处——对错误的扩展</strong>。</p><h2>资源清理</h2><p>出错后是需要做资源清理的，不同的编程语言有不同的资源清理的编程模式。</p><ul>\n<li>C语言：使用的是 <code>goto fail;</code> 的方式到一个集中的地方进行清理（给你推荐一篇有意思的文章《<a href=\"https://coolshell.cn/articles/11112.html\">由苹果的低级BUG想到的</a>》，你可以点击链接看一下）。</li>\n<li>C++语言：一般来说使用 <a href=\"https://en.wikipedia.org/wiki/Resource_acquisition_is_initialization\">RAII模式</a>，通过面向对象的代理模式，把需要清理的资源交给一个代理类，然后再析构函数来解决。</li>\n<li>Java语言：可以在finally 语句块里进行清理。</li>\n<li>Go语言：使用 <code>defer</code> 关键词进行清理。</li>\n</ul><p>下面是一个Go语言的资源清理的示例：</p><pre><code>func Close(c io.Closer) {\n  err := c.Close()\n  if err != nil {\n    log.Fatal(err)\n  }\n}\n\nfunc main() {\n  r, err := Open(&quot;a&quot;)\n  if err != nil {\n    log.Fatalf(&quot;error opening 'a'\\n&quot;)\n  }\n  defer Close(r) // 使用defer关键字在函数退出时关闭文件。\n\n  r, err = Open(&quot;b&quot;)\n  if err != nil {\n    log.Fatalf(&quot;error opening 'b'\\n&quot;)\n  }\n  defer Close(r) // 使用defer关键字在函数退出时关闭文件。\n}\n</code></pre><h2>Error Check Hell</h2><p>好了，说到 Go 语言的 <code>if err !=nil</code> 的代码了，这样的代码的确是能让人写到吐。那么有没有什么好的方式呢？有的。我们先看一个令人崩溃的代码。</p><pre><code>func parse(r io.Reader) (*Point, error) {\n\n    var p Point\n\n    if err := binary.Read(r, binary.BigEndian, &amp;p.Longitude); err != nil {\n        return nil, err\n    }\n    if err := binary.Read(r, binary.BigEndian, &amp;p.Latitude); err != nil {\n        return nil, err\n    }\n    if err := binary.Read(r, binary.BigEndian, &amp;p.Distance); err != nil {\n        return nil, err\n    }\n    if err := binary.Read(r, binary.BigEndian, &amp;p.ElevationGain); err != nil {\n        return nil, err\n    }\n    if err := binary.Read(r, binary.BigEndian, &amp;p.ElevationLoss); err != nil {\n        return nil, err\n    }\n}\n</code></pre><p>要解决这个事，我们可以用函数式编程的方式，如下代码示例：</p><pre><code>func parse(r io.Reader) (*Point, error) {\n    var p Point\n    var err error\n    read := func(data interface{}) {\n        if err != nil {\n            return\n        }\n        err = binary.Read(r, binary.BigEndian, data)\n    }\n\n    read(&amp;p.Longitude)\n    read(&amp;p.Latitude)\n    read(&amp;p.Distance)\n    read(&amp;p.ElevationGain)\n    read(&amp;p.ElevationLoss)\n\n    if err != nil {\n        return &amp;p, err\n    }\n    return &amp;p, nil\n}\n</code></pre><p>从这段代码中，我们可以看到，我们通过使用Closure 的方式把相同的代码给抽出来重新定义一个函数，这样大量的 <code>if err!=nil</code> 处理得很干净了，但是会带来一个问题，那就是有一个 <code>err</code> 变量和一个内部的函数，感觉不是很干净。</p><p>那么，我们还能不能搞得更干净一点呢？我们从Go 语言的 <code>bufio.Scanner()</code>中似乎可以学习到一些东西：</p><pre><code>scanner := bufio.NewScanner(input)\n\nfor scanner.Scan() {\n    token := scanner.Text()\n    // process token\n}\n\nif err := scanner.Err(); err != nil {\n    // process the error\n}\n</code></pre><p>可以看到，<code>scanner</code>在操作底层的I/O的时候，那个for-loop中没有任何的 <code>if err !=nil</code> 的情况，退出循环后有一个 <code>scanner.Err()</code> 的检查，看来使用了结构体的方式。模仿它，就可以对我们的代码进行重构了。</p><p>首先，定义一个结构体和一个成员函数：</p><pre><code>type Reader struct {\n    r   io.Reader\n    err error\n}\n\nfunc (r *Reader) read(data interface{}) {\n    if r.err == nil {\n        r.err = binary.Read(r.r, binary.BigEndian, data)\n    }\n}\n</code></pre><p>然后，我们的代码就可以变成下面这样：</p><pre><code>func parse(input io.Reader) (*Point, error) {\n    var p Point\n    r := Reader{r: input}\n\n    r.read(&amp;p.Longitude)\n    r.read(&amp;p.Latitude)\n    r.read(&amp;p.Distance)\n    r.read(&amp;p.ElevationGain)\n    r.read(&amp;p.ElevationLoss)\n\n    if r.err != nil {\n        return nil, r.err\n    }\n\n    return &amp;p, nil\n}\n</code></pre><p>有了刚刚的这个技术，我们的“<a href=\"https://martinfowler.com/bliki/FluentInterface.html\">流式接口 Fluent Interface</a>”也就很容易处理了。如下所示：</p><pre><code>package main\n\nimport (\n  &quot;bytes&quot;\n  &quot;encoding/binary&quot;\n  &quot;fmt&quot;\n)\n\n// 长度不够，少一个Weight\nvar b = []byte {0x48, 0x61, 0x6f, 0x20, 0x43, 0x68, 0x65, 0x6e, 0x00, 0x00, 0x2c} \nvar r = bytes.NewReader(b)\n\ntype Person struct {\n  Name [10]byte\n  Age uint8\n  Weight uint8\n  err error\n}\nfunc (p *Person) read(data interface{}) {\n  if p.err == nil {\n    p.err = binary.Read(r, binary.BigEndian, data)\n  }\n}\n\nfunc (p *Person) ReadName() *Person {\n  p.read(&amp;p.Name) \n  return p\n}\nfunc (p *Person) ReadAge() *Person {\n  p.read(&amp;p.Age) \n  return p\n}\nfunc (p *Person) ReadWeight() *Person {\n  p.read(&amp;p.Weight) \n  return p\n}\nfunc (p *Person) Print() *Person {\n  if p.err == nil {\n    fmt.Printf(&quot;Name=%s, Age=%d, Weight=%d\\n&quot;,p.Name, p.Age, p.Weight)\n  }\n  return p\n}\n\nfunc main() {   \n  p := Person{}\n  p.ReadName().ReadAge().ReadWeight().Print()\n  fmt.Println(p.err)  // EOF 错误\n}\n</code></pre><p>相信你应该看懂这个技巧了，不过，需要注意的是，它的使用场景是有局限的，也就只能在对于同一个业务对象的不断操作下可以简化错误处理，如果是多个业务对象，还是得需要各种 <code>if err != nil</code>的方式。</p><h2>包装错误</h2><p>最后，多说一句，我们需要包装一下错误，而不是干巴巴地把<code>err</code>返回到上层，我们需要把一些执行的上下文加入。</p><p>通常来说，我们会使用 <code>fmt.Errorf()</code>来完成这个事，比如：</p><pre><code>if err != nil {\n   return fmt.Errorf(&quot;something failed: %v&quot;, err)\n}\n</code></pre><p>另外，在Go语言的开发者中，更为普遍的做法是将错误包装在另一个错误中，同时保留原始内容：</p><pre><code>type authorizationError struct {\n    operation string\n    err error   // original error\n}\n\nfunc (e *authorizationError) Error() string {\n    return fmt.Sprintf(&quot;authorization failed during %s: %v&quot;, e.operation, e.err)\n}\n</code></pre><p>当然，更好的方式是通过一种标准的访问方法，这样，我们最好使用一个接口，比如 <code>causer</code>接口中实现 <code>Cause()</code> 方法来暴露原始错误，以供进一步检查：</p><pre><code>type causer interface {\n    Cause() error\n}\n\nfunc (e *authorizationError) Cause() error {\n    return e.err\n}\n</code></pre><p>这里有个好消息是，这样的代码不必再写了，有一个第三方的<a href=\"http://github.com/pkg/errors\">错误库</a>，对于这个库，我无论到哪儿都能看到它的存在，所以，这个基本上来说就是事实上的标准了。代码示例如下：</p><pre><code>import &quot;github.com/pkg/errors&quot;\n\n//错误包装\nif err != nil {\n    return errors.Wrap(err, &quot;read failed&quot;)\n}\n\n// Cause接口\nswitch err := errors.Cause(err).(type) {\ncase *MyError:\n    // handle specifically\ndefault:\n    // unknown error\n}\n</code></pre><h2>参考文章</h2><ul>\n<li><a href=\"http://jxck.hatenablog.com/entry/golang-error-handling-lesson-by-rob-pike\">Golang Error Handling lesson by Rob Pike</a></li>\n<li><a href=\"https://blog.golang.org/errors-are-values\">Errors are values</a></li>\n</ul><p>好了，这节课就到这里。如果你觉得今天的内容对你有所帮助，欢迎你帮我分享给更多人。</p>","comments":[{"had_liked":false,"id":274436,"user_name":"汪辉","can_delete":false,"product_type":"c1","uid":1625869,"ip_address":"","ucode":"2416B890609849","user_header":"https://static001.geekbang.org/account/avatar/00/18/cf/0d/a173e2b8.jpg","comment_is_top":false,"comment_ctime":1611021329,"is_pvip":false,"discussion_count":0,"race_medal":0,"score":"40265726993","product_id":100002201,"comment_content":"wrap和cause的错误包装在实际项目开发中非常有用，可以快速打印出错误栈，并根据err的类型做特殊处理，比如根据err级别进行不同的告警。我们这边常定义一个包含code和msg的struct，并实现Cause接口。出错的时候包上特定的错误码，最后根据Cause找出里面的错误码，设置不同的告警级别。","like_count":10},{"had_liked":false,"id":286364,"user_name":"@@fighting","can_delete":false,"product_type":"c1","uid":1236394,"ip_address":"","ucode":"7235C1E74549AE","user_header":"https://static001.geekbang.org/account/avatar/00/12/dd/aa/859544fd.jpg","comment_is_top":false,"comment_ctime":1617268779,"is_pvip":false,"discussion_count":1,"race_medal":0,"score":"23092105259","product_id":100002201,"comment_content":"Go 语言最新的 errors 包给出了 %w 的方式，而不是 github.com&#47;pkg&#47;errors 这个包","like_count":6,"discussions":[{"author":{"id":1058015,"avatar":"https://static001.geekbang.org/account/avatar/00/10/24/df/645f8087.jpg","nickname":"Yayu","note":"","ucode":"5E7842458D8229","race_medal":0,"user_type":1,"is_pvip":false},"reply_author":{"id":0,"avatar":"","nickname":"","note":"","ucode":"","race_medal":0,"user_type":1,"is_pvip":false},"discussion":{"id":367076,"discussion_content":"这个第三方的库兼容了go1.13的新特性，之所以没有金盆洗手，是因为go 的标准库还不支持携带堆栈信息，痛点。","likes_number":0,"is_delete":false,"is_hidden":false,"ctime":1618244057,"is_liked":false,"can_delete":false,"is_complain":false,"is_top":false,"parent_id":0,"ip_address":""},"score":2,"extra":"","child_discussion_number":0,"child_discussions":[]}]},{"had_liked":false,"id":285850,"user_name":"AlphaGao","can_delete":false,"product_type":"c1","uid":1111183,"ip_address":"","ucode":"862000415389FE","user_header":"https://static001.geekbang.org/account/avatar/00/10/f4/8f/06bd9544.jpg","comment_is_top":false,"comment_ctime":1617031413,"is_pvip":false,"discussion_count":1,"race_medal":0,"score":"5911998709","product_id":100002201,"comment_content":" 『Go 语言的资源清理的示例：』这里的代码是不是重复了","like_count":2,"discussions":[{"author":{"id":1020525,"avatar":"https://static001.geekbang.org/account/avatar/00/0f/92/6d/becd841a.jpg","nickname":"escray","note":"","ucode":"1F4204930E47C4","race_medal":2,"user_type":1,"is_pvip":true},"reply_author":{"id":0,"avatar":"","nickname":"","note":"","ucode":"","race_medal":0,"user_type":1,"is_pvip":false},"discussion":{"id":369479,"discussion_content":"应该不是重复，而是清理了两个资源，没有给出 Open 函数，可以假设是打开了一个文件","likes_number":0,"is_delete":false,"is_hidden":false,"ctime":1619053643,"is_liked":false,"can_delete":false,"is_complain":false,"is_top":false,"parent_id":0,"ip_address":""},"score":2,"extra":"","child_discussion_number":0,"child_discussions":[]}]},{"had_liked":false,"id":288802,"user_name":"Marvichov","can_delete":false,"product_type":"c1","uid":1111835,"ip_address":"","ucode":"7482099415C41C","user_header":"https://static001.geekbang.org/account/avatar/00/10/f7/1b/db7a0edc.jpg","comment_is_top":false,"comment_ctime":1618700981,"is_pvip":false,"discussion_count":0,"race_medal":0,"score":"1618700981","product_id":100002201,"comment_content":"&gt; There is one significant drawback to this approach, at least for some applications: there is no way to know how much of the processing completed before the error occurred. If that information is important, a more fine-grained approach is necessary. Often, though, an all-or-nothing check at the end is sufficient.<br><br>感觉应该加进`Error Check Hell` section. 不像exception, 你可以知道错在哪一步, this approach honors **all-or-nothing**","like_count":0},{"had_liked":false,"id":288801,"user_name":"Marvichov","can_delete":false,"product_type":"c1","uid":1111835,"ip_address":"","ucode":"7482099415C41C","user_header":"https://static001.geekbang.org/account/avatar/00/10/f7/1b/db7a0edc.jpg","comment_is_top":false,"comment_ctime":1618700472,"is_pvip":false,"discussion_count":0,"race_medal":0,"score":"1618700472","product_id":100002201,"comment_content":"nvm, the end of rob pike&#39;s article:<br><br>&gt; Finally, for the full story of my interaction with @jxck_, including a little video he recorded, visit his blog.","like_count":0},{"had_liked":false,"id":288800,"user_name":"Marvichov","can_delete":false,"product_type":"c1","uid":1111835,"ip_address":"","ucode":"7482099415C41C","user_header":"https://static001.geekbang.org/account/avatar/00/10/f7/1b/db7a0edc.jpg","comment_is_top":false,"comment_ctime":1618699659,"is_pvip":false,"discussion_count":0,"race_medal":0,"score":"1618699659","product_id":100002201,"comment_content":"`Golang Error Handling lesson by Rob Pike` (http:&#47;&#47;jxck.hatenablog.com&#47;entry&#47;golang-error-handling-lesson-by-rob-pike) 的链接里面是日文的. 正确的链接应该是第二个reference的链接?","like_count":1}]}