{"id":165164,"title":"93 | 如何在Swift里进行错误处理","content":"<p><strong>课件地址</strong></p><p><a href=\"https://gitee.com/geektime-geekbang/swift-course\">https://gitee.com/geektime-geekbang/swift-course</a></p>","comments":[{"had_liked":false,"id":164128,"user_name":"包罗万象","can_delete":false,"product_type":"c3","uid":1087130,"ip_address":"","ucode":"29AFA27338F0FB","user_header":"https://static001.geekbang.org/account/avatar/00/10/96/9a/78f2af55.jpg","comment_is_top":false,"comment_ctime":1576891438,"is_pvip":false,"replies":[{"id":62430,"content":"没有，就像其他语言里的抛出异常，你也可以通过返回不同的错误码表示出现错误。  但是统一的错误处理更优雅","user_name":"作者回复","user_name_real":"Geek_f72435","uid":1341726,"ctime":1576933769,"ip_address":"","comment_id":164128,"utype":1}],"discussion_count":2,"race_medal":0,"score":2,"product_id":100034001,"comment_content":"异常处理，跟其返回一个枚举，有什么区别呢？处理语法不同外，二者的本质区别是什么？","like_count":2,"discussions":[{"author":{"id":1341726,"avatar":"http://thirdwx.qlogo.cn/mmopen/vi_32/Q0j4TwGTfTLxtKhpmvzx2VB4iajicfJVFmQR3eP3xBpdpQEovpSqUfAOrNImvYwVb7P37ibI0ONziau9sbFEk8oDaA/132","nickname":"elfgate","note":"","ucode":"3C0B5F7C1F664C","race_medal":0,"user_type":2,"is_pvip":false},"reply_author":{"id":0,"avatar":"","nickname":"","note":"","ucode":"","race_medal":0,"user_type":1,"is_pvip":false},"discussion":{"id":478649,"discussion_content":"没有，就像其他语言里的抛出异常，你也可以通过返回不同的错误码表示出现错误。  但是统一的错误处理更优雅","likes_number":0,"is_delete":false,"is_hidden":false,"ctime":1576933769,"is_liked":false,"can_delete":false,"is_complain":false,"is_top":true,"parent_id":0,"ip_address":"","group_id":0},"score":2,"extra":"{\"reply\":true,\"user_type\":2}","child_discussion_number":0,"child_discussions":[]},{"author":{"id":1087130,"avatar":"https://static001.geekbang.org/account/avatar/00/10/96/9a/78f2af55.jpg","nickname":"包罗万象","note":"","ucode":"29AFA27338F0FB","race_medal":0,"user_type":1,"is_pvip":false},"reply_author":{"id":0,"avatar":"","nickname":"","note":"","ucode":"","race_medal":0,"user_type":1,"is_pvip":false},"discussion":{"id":94807,"discussion_content":"异常处理是否会像c++那样，有性能问题？","likes_number":0,"is_delete":false,"is_hidden":false,"ctime":1576990500,"is_liked":false,"can_delete":false,"is_complain":false,"is_top":false,"parent_id":0,"ip_address":"","group_id":0},"score":2,"extra":"","child_discussion_number":0,"child_discussions":[]}]},{"had_liked":false,"id":336658,"user_name":"Null","can_delete":false,"product_type":"c3","uid":1382587,"ip_address":"","ucode":"A7D4DF2A43C7D8","user_header":"https://static001.geekbang.org/account/avatar/00/15/18/bb/9299fab1.jpg","comment_is_top":false,"comment_ctime":1646277420,"is_pvip":false,"replies":null,"discussion_count":0,"race_medal":0,"score":2,"product_id":100034001,"comment_content":"补充几个注意：\n1. 任何调用带有throw关键字的方法，要么处理错误，要么继续传递，下面方法的try就是继续传递错误的形式。\nfunc buyFavoriteSnack(person: String, vendingMachine: VendingMachine) throws {\n    let snackName = favoriteSnacks[person] ?? &quot;Candy Bar&quot;\n    try vendingMachine.vend(itemNamed: snackName)\n}\n\n2.try?发生错误不会发生崩溃的理解\n如果不使用do-try-catch 直接去执行try，当前函数还不支持throw，那么执行try发生错误会崩溃。\n但是如果使用try？，即使当前函数不支持throw，也没有使用do-try-catch，也不会崩溃，而是返回一个可选值，值为nil。","like_count":0}]}